Workbook

Sheet Start here
A1: Sunday user test
A2: One 40-minute sermon, in Chinese or in English. Yellow cells are for writing. Gray cells calculate.
A4: Session
A5: Date
A6: Church
A7: Sermon language | B7: Chinese
A8: Headset direction | B8: Chinese → English
A9: Operator
A10: Listener
A12: Order
A13: 1. Fill in Before before the sermon starts. Click Test sound and confirm the chime.
A14: 2. On During, log each problem as it happens. Pick one type per row.
A15: 3. On Latency, around minutes 10, 20, 30, and 40, write how far behind the headset is.
A16: 4. On Smoothness, the operator counts connection problems. Leave 0 when nothing happened.
A17: 5. After the sermon, open After. Accuracy, glitches, breaks, lag, and the listener matrix are already totaled.
A19: What to write down
A20: Wrong meaning | B20: The headset said the wrong idea. How many is the number of sentences.
A21: Name / number / verse | B21: A person, a number, or a Bible reference was wrong. Church listeners notice these immediately.
A22: Glitch | B22: Repeated phrase, cut-off word, garbled speech, or a volume jump. Write 1 unless several sentences were affected.
A23: Break | B23: Translation audio stopped while the preacher was still talking. How many is the preacher sentences with no headset audio.
A24: Voice change | B24: Pitch, gender, age, or accent shifted, and the preacher did not hand off the microphone. Write 1.
A25: Hard to understand | B25: The words would not come clear, even when a meaning was present. How many is sentences.
A26: Mixed language | B26: The headset spoke the sermon language, or mixed both languages. Write 1 for each time.
A27: Lost the point | B27: You no longer knew what the preacher was saying. Write 1 for each time you had to find the thread again.
A28: Latency | B28: Count full sentences the preacher has finished that the headset has not said yet. If the headset is still inside the current sentence, count words instead. Use the Latency sheet, not During.
A29: Accuracy | B29: Talking minutes default to 30 inside a 40-minute sermon. Estimated sentences = talking minutes × 8. Accuracy uses wrong meaning plus names, numbers, and verses. Example: 240 sentences and 3 content errors is 98.8%.

Sheet Before
A1: Before the sermon
A2: Mark Pass or Fail. Chrome or Edge on the church computer.
A4: # | B4: Task | C4: Pass when | D4: Result | E4: Notes
A5: 1 | B5: Sign in with the church email and password. | C5: You reach Choose translation.
A6: 2 | B6: Open Chinese and English. | C6: The page shows this church, direction, audio in, audio out, and Start translation.
A7: 3 | B7: Choose the pulpit feed or mic, and the output that feeds the transmitter. | C7: Both are the devices you mean to use.
A8: 4 | B8: Click Test sound and listen on that output. | C8: You hear a short chime. Translation stays off. If it is quiet, raise Output volume and test again until the chime is clear.
A9: 5 | B9: Lock the direction to match this sermon: Chinese → English, or English → Chinese. | C9: The direction on screen matches the preacher.
A10: 6 | B10: Click Start translation. | C10: Status becomes Live. While the preacher speaks, the input meter moves and Output says Sending translation.
A11: 7 | B11: Scan the QR. When the phone says LIVE, tap Tap to Listen. | C11: The phone plays the translation.
A12: 8 | B12: After the sermon, click Stop translation, then Sign out. | C12: Status returns to Off, the headset goes quiet, and you are back on the login page.

Sheet During
A1: During the sermon
A2: One row per problem. Pick a type. How many is sentences for wrong meaning, names, breaks, and hard to understand. Write 1 for a glitch, a voice change, mixed language, or losing the point. Leave How many blank and Counted becomes 1. Leave unused rows blank.
A4: Minute | B4: Type | C4: How many | D4: What you heard | E4: What happened | F4: Counted
F5: =IF(B5="","",IF(C5="",1,C5))
F6: =IF(B6="","",IF(C6="",1,C6))
F7: =IF(B7="","",IF(C7="",1,C7))
F8: =IF(B8="","",IF(C8="",1,C8))
F9: =IF(B9="","",IF(C9="",1,C9))
F10: =IF(B10="","",IF(C10="",1,C10))
F11: =IF(B11="","",IF(C11="",1,C11))
F12: =IF(B12="","",IF(C12="",1,C12))
F13: =IF(B13="","",IF(C13="",1,C13))
F14: =IF(B14="","",IF(C14="",1,C14))
F15: =IF(B15="","",IF(C15="",1,C15))
F16: =IF(B16="","",IF(C16="",1,C16))
... F84: =IF(B84="","",IF(C84="",1,C84))

Sheet Latency
A1: Latency
A2: Four checks, around minutes 10, 20, 30, and 40. Sentences behind means full sentences the preacher has finished that the headset has not said yet. Words behind is for when the headset is still inside the current sentence. Fill one number on each row.
A4: Around minute | B4: Sentences behind | C4: Words behind | D4: What the preacher had just finished
A5: 10
A6: 20
A7: 30
A8: 40
A10: Worst besides these checks
A11: Worst you noticed
A13: This sermon
A14: Average sentences behind | B14: =IF(COUNT(B5:B8)=0,"",AVERAGE(B5:B8))
A15: Worst sentences behind | B15: =IF(COUNT(B5:B8)=0,"",MAX(B5:B8))
A16: Average words behind | B16: =IF(COUNT(C5:C8)=0,"",AVERAGE(C5:C8))
A17: Worst words behind | B17: =IF(COUNT(C5:C8)=0,"",MAX(C5:C8))

Sheet Smoothness
A1: Operation and connection
A2: Count each time the connection or the page needed a person. Leave 0 when it did not happen. The listener can add a note when the headset or the phone was the side that failed.
A4: Event | B4: Times | C4: Notes
A5: Left Live or showed Reconnecting | B5: 0
A6: Clicked Reconnect or Start again | B6: 0
A7: Phone stalled while the headset continued | B7: 0
A8: Headset went quiet while the phone continued | B8: 0
A9: Had to refresh the page | B9: 0
A11: Whole sermon
A12: Headset stayed usable the whole sermon
A13: Phone stayed usable the whole sermon
A14: Overall connection

Sheet After
A1: After the sermon
A2: Gray cells read During, Latency, and Smoothness. Type the talking minutes if pauses were timed. Otherwise leave 30.
A4: Accuracy
A5: Talking minutes | B5: 30 | C5: Use 30 when pauses were not timed.
A6: Sentences per talking minute | B6: 8 | C6: About 8 sentences a minute in Chinese or in English.
A7: Estimated sentences | B7: =B5*B6 | C7: Talking minutes × 8.
A8: Content errors | B8: =SUMIF(During!$B$5:$B$84,"Wrong meaning",During!$F$5:$F$84)+SUMIF(During!$B$5:$B$84,"Name / number / verse",During!$F$5:$F$84) | C8: Wrong meaning, plus names, numbers, and verses.
A9: Accuracy | B9: =IF(B7=0,"",(B7-B8)/B7) | C9: (Estimated sentences − content errors) ÷ estimated sentences.
A10: Sentences the listener could not use | B10: =B8+SUMIF(During!$B$5:$B$84,"Break",During!$F$5:$F$84)+SUMIF(During!$B$5:$B$84,"Hard to understand",During!$F$5:$F$84) | C10: Content errors, plus sentences lost in breaks, plus sentences that were hard to understand.
A12: What listeners noticed
A13: What | B13: Times | C13: How many | D13: Per 10 minutes | E13: Listeners care because
A14: Wrong meaning | B14: =COUNTIF(During!$B$5:$B$84,A14) | C14: =SUMIF(During!$B$5:$B$84,A14,During!$F$5:$F$84) | D14: =B14/4 | E14: The idea itself was wrong.
A15: Name / number / verse | B15: =COUNTIF(During!$B$5:$B$84,A15) | C15: =SUMIF(During!$B$5:$B$84,A15,During!$F$5:$F$84) | D15: =B15/4 | E15: A wrong name or verse is obvious in the room.
A16: Break | B16: =COUNTIF(During!$B$5:$B$84,A16) | C16: =SUMIF(During!$B$5:$B$84,A16,During!$F$5:$F$84) | D16: =B16/4 | E16: Silence while the preacher is still talking.
A17: Repeated phrase | B17: =COUNTIF(During!$B$5:$B$84,A17) | C17: =SUMIF(During!$B$5:$B$84,A17,During!$F$5:$F$84) | D17: =B17/4 | E17: The same words came around again.
A18: Cut-off word | B18: =COUNTIF(During!$B$5:$B$84,A18) | C18: =SUMIF(During!$B$5:$B$84,A18,During!$F$5:$F$84) | D18: =B18/4 | E18: A word started and did not finish.
A19: Garbled speech | B19: =COUNTIF(During!$B$5:$B$84,A19) | C19: =SUMIF(During!$B$5:$B$84,A19,During!$F$5:$F$84) | D19: =B19/4 | E19: A burst could not be parsed as words.
A20: Volume jump | B20: =COUNTIF(During!$B$5:$B$84,A20) | C20: =SUMIF(During!$B$5:$B$84,A20,During!$F$5:$F$84) | D20: =B20/4 | E20: Loudness leapt without anyone touching the knob.
A21: Voice change | B21: =COUNTIF(During!$B$5:$B$84,A21) | C21: =SUMIF(During!$B$5:$B$84,A21,During!$F$5:$F$84) | D21: =B21/4 | E21: The speaker seemed to become someone else.
A22: Hard to understand | B22: =COUNTIF(During!$B$5:$B$84,A22) | C22: =SUMIF(During!$B$5:$B$84,A22,During!$F$5:$F$84) | D22: =B22/4 | E22: Meaning may have been there, but the words were not clear.
A23: Mixed language | B23: =COUNTIF(During!$B$5:$B$84,A23) | C23: =SUMIF(During!$B$5:$B$84,A23,During!$F$5:$F$84) | D23: =B23/4 | E23: The headset used the sermon language or mixed both.
A24: Lost the point | B24: =COUNTIF(During!$B$5:$B$84,A24) | C24: =SUMIF(During!$B$5:$B$84,A24,During!$F$5:$F$84) | D24: =B24/4 | E24: The listener had to find the preacher's thread again.
A25: All glitches | B25: =COUNTIF(During!$B$5:$B$84,"Repeated phrase")+COUNTIF(During!$B$5:$B$84,"Cut-off word")+COUNTIF(During!$B$5:$B$84,"Garbled speech")+COUNTIF(During!$B$5:$B$84,"Volume jump") | C25: =SUMIF(During!$B$5:$B$84,"Repeated phrase",During!$F$5:$F$84)+SUMIF(During!$B$5:$B$84,"Cut-off word",During!$F$5:$F$84)+SUMIF(During!$B$5:$B$84,"Garbled speech",During!$F$5:$F$84)+SUMIF(During!$B$5:$B$84,"Volume jump",During!$F$5:$F$84) | D25: =B25/4 | E25: Repeated phrases, cut-off words, garbled speech, and volume jumps.
A27: Latency
A28: Check | B28: Sentences | C28: Words
A29: Average of the four checks | B29: =Latency!B14 | C29: =Latency!B16
A30: Worst of the four checks | B30: =Latency!B15 | C30: =Latency!B17
A31: Worst you noticed besides the checks | B31: =Latency!B11 | C31: =Latency!C11
A33: Operation and connection
A34: Event | B34: Times
A35: Left Live or showed Reconnecting | B35: =Smoothness!B5
A36: Clicked Reconnect or Start again | B36: =Smoothness!B6
A37: Phone stalled while the headset continued | B37: =Smoothness!B7
A38: Headset went quiet while the phone continued | B38: =Smoothness!B8
A39: Had to refresh the page | B39: =Smoothness!B9
A40: Headset stayed usable the whole sermon | B40: =Smoothness!B12
A41: Phone stayed usable the whole sermon | B41: =Smoothness!B13
A42: Overall connection | B42: =Smoothness!B14
A44: A more human voice would have
A45: Mark Yes when this sermon had that quality. One steady voice, emphasis that follows the preacher, breaths, varied endings, natural names, and a pace that speeds up and slows down with the preacher make the voice sound less like AI.
...
